Workbook

Sheet README
A1: Exam Prep Resource Directory - dMAT | GRE | IELTS | GMAT
A3: About this Document :
A4: This sheet is a centralized repository of preparation resources, practice material, tools, and notes for the dMAT, GRE, and IELTS exams. To maintain data integrity, direct editing is restricted.
A6: Directory Structure :
A7: • ALL Material: Consolidated master list across all exams with filterable tags.
A8: • dMAT: Preparation material, question sets, and notes specific to the dMAT.
A9: • GRE: Quant, Verbal, and AWA prep guides, vocabulary decks, and test links.
A10: • IELTS: Academic and General training material for Reading, Writing, Listening, and Speaking.
A12: Submissions & Suggestions :
A13: If you have verified material, practice sets, or useful links to contribute:
A14: • Join the Germany Launchpad community on Whatsapp
A15: • WhatsApp Link here: https://chat.whatsapp.com/K7pa3HJ22CU5Tg5T8zzJqJ
... A21: If you encounter broken links, inaccessible Drive permissions, or outdated material, please email or contact on whatsapp; details and Sheet ID/Row number so it can be updated or removed.

Sheet ALL Resources
A1: ID | B1: EXAM | C1: Resource | D1: Type | E1: Link | F1: Notes | G1: Added by
A2: dMAT-001 | B2: =IF(A2="","",IF(COUNTIF(dMAT!A:A,A2)>0,"dMAT",IF(COUNTIF(GRE!A:A,A2)>0,"GRE",IF(COUNTIF(IELTS!A:A,A2)>0,"IELTS",IF(COUNTIF(GMAT!A:A,A2)>0,"GMAT",IF(COUNTIF(German!A:A,A2)>0,"GERMAN",IF(COUNTIF(Temp!A:A,A2)>0,"TEMP","Not Found"))))))) -> dMAT | C2: {=IF(A2="","",IFNA(_xlfn.XLOOKUP(A2,dMAT!A:A,dMAT!B:F),IFNA(_xlfn.XLOOKUP(A2,GRE!A:A,GRE!B:F),IFNA(_xlfn.XLOOKUP(A2,IELTS!A:A,IELTS!B:F),IFNA(_xlfn.XLOOKUP(A2,GMAT!A:A,GMAT!B:F),IFNA(_xlfn.XLOOKUP(A2,German!A:A,German!B:F),IFNA(_xlfn.XLOOKUP(A2,Temp!A:A,Temp!B:F),"Not Found")))))))} -> dmatprep | D2: Official material | E2: https://drive.google.com/file/d/1ysGWxS0mbBrH8fSVKJ1TkojYYCTuOJxz/view?usp=drive_link | F2: Official main material
A3: dMAT-002 | B3: =IF(A3="","",IF(COUNTIF(dMAT!A:A,A3)>0,"dMAT",IF(COUNTIF(GRE!A:A,A3)>0,"GRE",IF(COUNTIF(IELTS!A:A,A3)>0,"IELTS",IF(COUNTIF(GMAT!A:A,A3)>0,"GMAT",IF(COUNTIF(German!A:A,A3)>0,"GERMAN","Not Found")))))) -> dMAT | C3: {=IF(A3="","",IFNA(_xlfn.XLOOKUP(A3,dMAT!A:A,dMAT!B:F),IFNA(_xlfn.XLOOKUP(A3,GRE!A:A,GRE!B:F),IFNA(_xlfn.XLOOKUP(A3,IELTS!A:A,IELTS!B:F),IFNA(_xlfn.XLOOKUP(A3,GMAT!A:A,GMAT!B:F),IFNA(_xlfn.XLOOKUP(A3,German!A:A,German!B:F),"Not Found"))))))} -> Vercel App | D3: Mock test | E3: https://dmatprep.vercel.app/
A4: dMAT-003 | B4: =IF(A4="","",IF(COUNTIF(dMAT!A:A,A4)>0,"dMAT",IF(COUNTIF(GRE!A:A,A4)>0,"GRE",IF(COUNTIF(IELTS!A:A,A4)>0,"IELTS",IF(COUNTIF(GMAT!A:A,A4)>0,"GMAT",IF(COUNTIF(German!A:A,A4)>0,"GERMAN","Not Found")))))) -> dMAT | C4: {=IF(A4="","",IFNA(_xlfn.XLOOKUP(A4,dMAT!A:A,dMAT!B:F),IFNA(_xlfn.XLOOKUP(A4,GRE!A:A,GRE!B:F),IFNA(_xlfn.XLOOKUP(A4,IELTS!A:A,IELTS!B:F),IFNA(_xlfn.XLOOKUP(A4,GMAT!A:A,GMAT!B:F),IFNA(_xlfn.XLOOKUP(A4,German!A:A,German!B:F),"Not Found"))))))} -> dMAT practice (meghchevli) | D4: Practice app | E4: https://dmat.meghchevli.qzz.io/
A5: dMAT-004 | B5: =IF(A5="","",IF(COUNTIF(dMAT!A:A,A5)>0,"dMAT",IF(COUNTIF(GRE!A:A,A5)>0,"GRE",IF(COUNTIF(IELTS!A:A,A5)>0,"IELTS",IF(COUNTIF(GMAT!A:A,A5)>0,"GMAT",IF(COUNTIF(German!A:A,A5)>0,"GERMAN","Not Found")))))) -> dMAT | C5: {=IF(A5="","",IFNA(_xlfn.XLOOKUP(A5,dMAT!A:A,dMAT!B:F),IFNA(_xlfn.XLOOKUP(A5,GRE!A:A,GRE!B:F),IFNA(_xlfn.XLOOKUP(A5,IELTS!A:A,IELTS!B:F),IFNA(_xlfn.XLOOKUP(A5,GMAT!A:A,GMAT!B:F),IFNA(_xlfn.XLOOKUP(A5,German!A:A,German!B:F),"Not Found"))))))} -> Latin Square practice | D5: Practice app | E5: https://latinsquare.vercel.app/ | F5: no account needed
A6: dMAT-005 | B6: =IF(A6="","",IF(COUNTIF(dMAT!A:A,A6)>0,"dMAT",IF(COUNTIF(GRE!A:A,A6)>0,"GRE",IF(COUNTIF(IELTS!A:A,A6)>0,"IELTS",IF(COUNTIF(GMAT!A:A,A6)>0,"GMAT",IF(COUNTIF(German!A:A,A6)>0,"GERMAN","Not Found")))))) -> dMAT | C6: {=IF(A6="","",IFNA(_xlfn.XLOOKUP(A6,dMAT!A:A,dMAT!B:F),IFNA(_xlfn.XLOOKUP(A6,GRE!A:A,GRE!B:F),IFNA(_xlfn.XLOOKUP(A6,IELTS!A:A,IELTS!B:F),IFNA(_xlfn.XLOOKUP(A6,GMAT!A:A,GMAT!B:F),IFNA(_xlfn.XLOOKUP(A6,German!A:A,German!B:F),"Not Found"))))))} -> Nbyula dMAT guide | D6: PDF / Guide | E6: https://drive.google.com/file/d/1k816pc1ecIx-UReevHwMbee42DrjhHS-/view?usp=sharing
A7: dMAT-006 | B7: =IF(A7="","",IF(COUNTIF(dMAT!A:A,A7)>0,"dMAT",IF(COUNTIF(GRE!A:A,A7)>0,"GRE",IF(COUNTIF(IELTS!A:A,A7)>0,"IELTS",IF(COUNTIF(GMAT!A:A,A7)>0,"GMAT",IF(COUNTIF(German!A:A,A7)>0,"GERMAN","Not Found")))))) -> dMAT | C7: {=IF(A7="","",IFNA(_xlfn.XLOOKUP(A7,dMAT!A:A,dMAT!B:F),IFNA(_xlfn.XLOOKUP(A7,GRE!A:A,GRE!B:F),IFNA(_xlfn.XLOOKUP(A7,IELTS!A:A,IELTS!B:F),IFNA(_xlfn.XLOOKUP(A7,GMAT!A:A,GMAT!B:F),IFNA(_xlfn.XLOOKUP(A7,German!A:A,German!B:F),"Not Found"))))))} -> dMAT Grid mock test | D7: Mock test | E7: https://www.dmatgrid.com/mock-test
A8: dMAT-007 | B8: =IF(A8="","",IF(COUNTIF(dMAT!A:A,A8)>0,"dMAT",IF(COUNTIF(GRE!A:A,A8)>0,"GRE",IF(COUNTIF(IELTS!A:A,A8)>0,"IELTS",IF(COUNTIF(GMAT!A:A,A8)>0,"GMAT",IF(COUNTIF(German!A:A,A8)>0,"GERMAN","Not Found")))))) -> dMAT | C8: {=IF(A8="","",IFNA(_xlfn.XLOOKUP(A8,dMAT!A:A,dMAT!B:F),IFNA(_xlfn.XLOOKUP(A8,GRE!A:A,GRE!B:F),IFNA(_xlfn.XLOOKUP(A8,IELTS!A:A,IELTS!B:F),IFNA(_xlfn.XLOOKUP(A8,GMAT!A:A,GMAT!B:F),IFNA(_xlfn.XLOOKUP(A8,German!A:A,German!B:F),"Not Found"))))))} -> dMat Prep | D8: Mock test | E8: https://dmat-prep.in/ | F8: not a lot of free qs, good for gam
A9: dMAT-008 | B9: =IF(A9="","",IF(COUNTIF(dMAT!A:A,A9)>0,"dMAT",IF(COUNTIF(GRE!A:A,A9)>0,"GRE",IF(COUNTIF(IELTS!A:A,A9)>0,"IELTS",IF(COUNTIF(GMAT!A:A,A9)>0,"GMAT",IF(COUNTIF(German!A:A,A9)>0,"GERMAN","Not Found")))))) -> dMAT | C9: {=IF(A9="","",IFNA(_xlfn.XLOOKUP(A9,dMAT!A:A,dMAT!B:F),IFNA(_xlfn.XLOOKUP(A9,GRE!A:A,GRE!B:F),IFNA(_xlfn.XLOOKUP(A9,IELTS!A:A,IELTS!B:F),IFNA(_xlfn.XLOOKUP(A9,GMAT!A:A,GMAT!B:F),IFNA(_xlfn.XLOOKUP(A9,German!A:A,German!B:F),"Not Found"))))))} -> dMAT exam structure | D9: PDF / Guide | E9: https://www.d-mat.de/en/
A10: dMAT-009 | B10: =IF(A10="","",IF(COUNTIF(dMAT!A:A,A10)>0,"dMAT",IF(COUNTIF(GRE!A:A,A10)>0,"GRE",IF(COUNTIF(IELTS!A:A,A10)>0,"IELTS",IF(COUNTIF(GMAT!A:A,A10)>0,"GMAT",IF(COUNTIF(German!A:A,A10)>0,"GERMAN","Not Found")))))) -> dMAT | C10: {=IF(A10="","",IFNA(_xlfn.XLOOKUP(A10,dMAT!A:A,dMAT!B:F),IFNA(_xlfn.XLOOKUP(A10,GRE!A:A,GRE!B:F),IFNA(_xlfn.XLOOKUP(A10,IELTS!A:A,IELTS!B:F),IFNA(_xlfn.XLOOKUP(A10,GMAT!A:A,GMAT!B:F),IFNA(_xlfn.XLOOKUP(A10,German!A:A,German!B:F),"Not Found"))))))} -> Prompt for generating practice questions | D10: Prompt | E10: drive.google.com/file/d/14bkiXQx7qRyhANeGg8nJ0-OHFDwzdAFA/view?usp=drive_link | F10: File access is not given.
A11: dMAT-010 | B11: =IF(A11="","",IF(COUNTIF(dMAT!A:A,A11)>0,"dMAT",IF(COUNTIF(GRE!A:A,A11)>0,"GRE",IF(COUNTIF(IELTS!A:A,A11)>0,"IELTS",IF(COUNTIF(GMAT!A:A,A11)>0,"GMAT",IF(COUNTIF(German!A:A,A11)>0,"GERMAN","Not Found")))))) -> dMAT | C11: {=IF(A11="","",IFNA(_xlfn.XLOOKUP(A11,dMAT!A:A,dMAT!B:F),IFNA(_xlfn.XLOOKUP(A11,GRE!A:A,GRE!B:F),IFNA(_xlfn.XLOOKUP(A11,IELTS!A:A,IELTS!B:F),IFNA(_xlfn.XLOOKUP(A11,GMAT!A:A,GMAT!B:F),IFNA(_xlfn.XLOOKUP(A11,German!A:A,German!B:F),"Not Found"))))))} -> Career Wise - free dMAT practice app and mock test (APS India) | D11: Mock test | E11: https://www.careerwiseedu.com/dmat-aps-mock-test | F11: Best for full mock test but latin sq are quite easier
A12: dMAT-011 | B12: =IF(A12="","",IF(COUNTIF(dMAT!A:A,A12)>0,"dMAT",IF(COUNTIF(GRE!A:A,A12)>0,"GRE",IF(COUNTIF(IELTS!A:A,A12)>0,"IELTS",IF(COUNTIF(GMAT!A:A,A12)>0,"GMAT",IF(COUNTIF(German!A:A,A12)>0,"GERMAN","Not Found")))))) -> dMAT | C12: {=IF(A12="","",IFNA(_xlfn.XLOOKUP(A12,dMAT!A:A,dMAT!B:F),IFNA(_xlfn.XLOOKUP(A12,GRE!A:A,GRE!B:F),IFNA(_xlfn.XLOOKUP(A12,IELTS!A:A,IELTS!B:F),IFNA(_xlfn.XLOOKUP(A12,GMAT!A:A,GMAT!B:F),IFNA(_xlfn.XLOOKUP(A12,German!A:A,German!B:F),"Not Found"))))))} -> dMAT Core module Practice | D12: Mock test | E12: https://dmat-website.vercel.app/ | F12: only core module hard questions
A13: dMAT-012 | B13: =IF(A13="","",IF(COUNTIF(dMAT!A:A,A13)>0,"dMAT",IF(COUNTIF(GRE!A:A,A13)>0,"GRE",IF(COUNTIF(IELTS!A:A,A13)>0,"IELTS",IF(COUNTIF(GMAT!A:A,A13)>0,"GMAT",IF(COUNTIF(German!A:A,A13)>0,"GERMAN","Not Found")))))) -> dMAT | C13: {=IF(A13="","",IFNA(_xlfn.XLOOKUP(A13,dMAT!A:A,dMAT!B:F),IFNA(_xlfn.XLOOKUP(A13,GRE!A:A,GRE!B:F),IFNA(_xlfn.XLOOKUP(A13,IELTS!A:A,IELTS!B:F),IFNA(_xlfn.XLOOKUP(A13,GMAT!A:A,GMAT!B:F),IFNA(_xlfn.XLOOKUP(A13,German!A:A,German!B:F),"Not Found"))))))} -> TestAs Guide for General Academic Module prep | D13: Mock test | E13: https://www.testas.de/fileadmin/bilder/4_pdf-video/1-teilnehmende/230531_digitalertestas_preparatory_materials.pdf
A14: dMAT-013 | B14: =IF(A14="","",IF(COUNTIF(dMAT!A:A,A14)>0,"dMAT",IF(COUNTIF(GRE!A:A,A14)>0,"GRE",IF(COUNTIF(IELTS!A:A,A14)>0,"IELTS",IF(COUNTIF(GMAT!A:A,A14)>0,"GMAT",IF(COUNTIF(German!A:A,A14)>0,"GERMAN","Not Found")))))) -> dMAT | C14: {=IF(A14="","",IFNA(_xlfn.XLOOKUP(A14,dMAT!A:A,dMAT!B:F),IFNA(_xlfn.XLOOKUP(A14,GRE!A:A,GRE!B:F),IFNA(_xlfn.XLOOKUP(A14,IELTS!A:A,IELTS!B:F),IFNA(_xlfn.XLOOKUP(A14,GMAT!A:A,GMAT!B:F),IFNA(_xlfn.XLOOKUP(A14,German!A:A,German!B:F),"Not Found"))))))} -> Dmat Practice platform | D14: Practice app | E14: http://datasnap.in/
A15: dMAT-014 | B15: =IF(A15="","",IF(COUNTIF(dMAT!A:A,A15)>0,"dMAT",IF(COUNTIF(GRE!A:A,A15)>0,"GRE",IF(COUNTIF(IELTS!A:A,A15)>0,"IELTS",IF(COUNTIF(GMAT!A:A,A15)>0,"GMAT",IF(COUNTIF(German!A:A,A15)>0,"GERMAN","Not Found")))))) -> dMAT | C15: {=IF(A15="","",IFNA(_xlfn.XLOOKUP(A15,dMAT!A:A,dMAT!B:F),IFNA(_xlfn.XLOOKUP(A15,GRE!A:A,GRE!B:F),IFNA(_xlfn.XLOOKUP(A15,IELTS!A:A,IELTS!B:F),IFNA(_xlfn.XLOOKUP(A15,GMAT!A:A,GMAT!B:F),IFNA(_xlfn.XLOOKUP(A15,German!A:A,German!B:F),"Not Found"))))))} -> Dmat practice and mock test (subject module included - unofficial) | D15: Mock test | E15: https://dmat2026.vercel.app/ | F15: No account and no payment
A16: dMAT-015 | B16: =IF(A16="","",IF(COUNTIF(dMAT!A:A,A16)>0,"dMAT",IF(COUNTIF(GRE!A:A,A16)>0,"GRE",IF(COUNTIF(IELTS!A:A,A16)>0,"IELTS",IF(COUNTIF(GMAT!A:A,A16)>0,"GMAT",IF(COUNTIF(German!A:A,A16)>0,"GERMAN","Not Found")))))) -> dMAT | C16: {=IF(A16="","",IFNA(_xlfn.XLOOKUP(A16,dMAT!A:A,dMAT!B:F),IFNA(_xlfn.XLOOKUP(A16,GRE!A:A,GRE!B:F),IFNA(_xlfn.XLOOKUP(A16,IELTS!A:A,IELTS!B:F),IFNA(_xlfn.XLOOKUP(A16,GMAT!A:A,GMAT!B:F),IFNA(_xlfn.XLOOKUP(A16,German!A:A,German!B:F),"Not Found"))))))} -> Official Information Guideline for exam | D16: PDF / Guide | E16: https://drive.google.com/file/d/1v1852TLaww_cDXoQRUsDGU_iZYKcpeXU/view?usp=drive_link
A17: dMAT-016 | B17: =IF(A17="","",IF(COUNTIF(dMAT!A:A,A17)>0,"dMAT",IF(COUNTIF(GRE!A:A,A17)>0,"GRE",IF(COUNTIF(IELTS!A:A,A17)>0,"IELTS",IF(COUNTIF(GMAT!A:A,A17)>0,"GMAT",IF(COUNTIF(German!A:A,A17)>0,"GERMAN","Not Found")))))) -> dMAT | C17: {=IF(A17="","",IFNA(_xlfn.XLOOKUP(A17,dMAT!A:A,dMAT!B:F),IFNA(_xlfn.XLOOKUP(A17,GRE!A:A,GRE!B:F),IFNA(_xlfn.XLOOKUP(A17,IELTS!A:A,IELTS!B:F),IFNA(_xlfn.XLOOKUP(A17,GMAT!A:A,GMAT!B:F),IFNA(_xlfn.XLOOKUP(A17,German!A:A,German!B:F),"Not Found"))))))} -> Latin Square with the timer. | D17: Practice app | E17: https://naikigai.github.io/Dmat-Practice/latin-squares.html
A18: dMAT-017 | B18: =IF(A18="","",IF(COUNTIF(dMAT!A:A,A18)>0,"dMAT",IF(COUNTIF(GRE!A:A,A18)>0,"GRE",IF(COUNTIF(IELTS!A:A,A18)>0,"IELTS",IF(COUNTIF(GMAT!A:A,A18)>0,"GMAT",IF(COUNTIF(German!A:A,A18)>0,"GERMAN","Not Found")))))) -> dMAT | C18: {=IF(A18="","",IFNA(_xlfn.XLOOKUP(A18,dMAT!A:A,dMAT!B:F),IFNA(_xlfn.XLOOKUP(A18,GRE!A:A,GRE!B:F),IFNA(_xlfn.XLOOKUP(A18,IELTS!A:A,IELTS!B:F),IFNA(_xlfn.XLOOKUP(A18,GMAT!A:A,GMAT!B:F),IFNA(_xlfn.XLOOKUP(A18,German!A:A,German!B:F),"Not Found"))))))} -> General Module Preparation Questions | D18: PDF / Guide | E18: https://drive.google.com/file/d/1gkiuCug_o6I8RxjqFLIAHfRf7a6MvJJJ/view?usp=sharing | F18: great
A19: dMAT-018 | B19: =IF(A19="","",IF(COUNTIF(dMAT!A:A,A19)>0,"dMAT",IF(COUNTIF(GRE!A:A,A19)>0,"GRE",IF(COUNTIF(IELTS!A:A,A19)>0,"IELTS",IF(COUNTIF(GMAT!A:A,A19)>0,"GMAT",IF(COUNTIF(German!A:A,A19)>0,"GERMAN","Not Found")))))) -> dMAT | C19: {=IF(A19="","",IFNA(_xlfn.XLOOKUP(A19,dMAT!A:A,dMAT!B:F),IFNA(_xlfn.XLOOKUP(A19,GRE!A:A,GRE!B:F),IFNA(_xlfn.XLOOKUP(A19,IELTS!A:A,IELTS!B:F),IFNA(_xlfn.XLOOKUP(A19,GMAT!A:A,GMAT!B:F),IFNA(_xlfn.XLOOKUP(A19,German!A:A,German!B:F),"Not Found"))))))} -> Economics, Social Science, Computational Science Prep | D19: PDF / Guide | E19: https://drive.google.com/file/d/1IqhIaVy6nXQTwI5VTvEkAhM-ExodirxC/view?usp=sharing
A20: dMAT-019 | B20: =IF(A20="","",IF(COUNTIF(dMAT!A:A,A20)>0,"dMAT",IF(COUNTIF(GRE!A:A,A20)>0,"GRE",IF(COUNTIF(IELTS!A:A,A20)>0,"IELTS",IF(COUNTIF(GMAT!A:A,A20)>0,"GMAT",IF(COUNTIF(German!A:A,A20)>0,"GERMAN","Not Found")))))) -> dMAT | C20: {=IF(A20="","",IFNA(_xlfn.XLOOKUP(A20,dMAT!A:A,dMAT!B:F),IFNA(_xlfn.XLOOKUP(A20,GRE!A:A,GRE!B:F),IFNA(_xlfn.XLOOKUP(A20,IELTS!A:A,IELTS!B:F),IFNA(_xlfn.XLOOKUP(A20,GMAT!A:A,GMAT!B:F),IFNA(_xlfn.XLOOKUP(A20,German!A:A,German!B:F),"Not Found"))))))} -> latin square tips and practice | D20: Practice app | E20: https://latin-squares-tips.vercel.app/
A21: dMAT-020 | B21: =IF(A21="","",IF(COUNTIF(dMAT!A:A,A21)>0,"dMAT",IF(COUNTIF(GRE!A:A,A21)>0,"GRE",IF(COUNTIF(IELTS!A:A,A21)>0,"IELTS",IF(COUNTIF(GMAT!A:A,A21)>0,"GMAT",IF(COUNTIF(German!A:A,A21)>0,"GERMAN","Not Found")))))) -> dMAT | C21: {=IF(A21="","",IFNA(_xlfn.XLOOKUP(A21,dMAT!A:A,dMAT!B:F),IFNA(_xlfn.XLOOKUP(A21,GRE!A:A,GRE!B:F),IFNA(_xlfn.XLOOKUP(A21,IELTS!A:A,IELTS!B:F),IFNA(_xlfn.XLOOKUP(A21,GMAT!A:A,GMAT!B:F),IFNA(_xlfn.XLOOKUP(A21,German!A:A,German!B:F),"Not Found"))))))} -> Latin Squares Generator TestAS(Recep Dayi) | D21: Practice app | E21: https://recepdayi.com.tr/en/digital-testas-exams-latin-squares/
A22: GRE-001 | B22: =IF(A22="","",IF(COUNTIF(dMAT!A:A,A22)>0,"dMAT",IF(COUNTIF(GRE!A:A,A22)>0,"GRE",IF(COUNTIF(IELTS!A:A,A22)>0,"IELTS",IF(COUNTIF(GMAT!A:A,A22)>0,"GMAT",IF(COUNTIF(German!A:A,A22)>0,"GERMAN","Not Found")))))) -> GRE | C22: {=IF(A22="","",IFNA(_xlfn.XLOOKUP(A22,dMAT!A:A,dMAT!B:F),IFNA(_xlfn.XLOOKUP(A22,GRE!A:A,GRE!B:F),IFNA(_xlfn.XLOOKUP(A22,IELTS!A:A,IELTS!B:F),IFNA(_xlfn.XLOOKUP(A22,GMAT!A:A,GMAT!B:F),IFNA(_xlfn.XLOOKUP(A22,German!A:A,German!B:F),"Not Found"))))))} -> GRE RESOURCES - shared Drive folder | D22: Other | E22: https://drive.google.com/drive/folders/1yTME8yAtEOoD5JYNelwq5O3FLp-tueJL | F22: Whole folder. Every file inside it is listed individually below.
A23: GRE-002 | B23: =IF(A23="","",IF(COUNTIF(dMAT!A:A,A23)>0,"dMAT",IF(COUNTIF(GRE!A:A,A23)>0,"GRE",IF(COUNTIF(IELTS!A:A,A23)>0,"IELTS",IF(COUNTIF(GMAT!A:A,A23)>0,"GMAT",IF(COUNTIF(German!A:A,A23)>0,"GERMAN","Not Found")))))) -> GRE | C23: {=IF(A23="","",IFNA(_xlfn.XLOOKUP(A23,dMAT!A:A,dMAT!B:F),IFNA(_xlfn.XLOOKUP(A23,GRE!A:A,GRE!B:F),IFNA(_xlfn.XLOOKUP(A23,IELTS!A:A,IELTS!B:F),IFNA(_xlfn.XLOOKUP(A23,GMAT!A:A,GMAT!B:F),IFNA(_xlfn.XLOOKUP(A23,German!A:A,German!B:F),"Not Found"))))))} -> Gregmat Website | D23: Website | E23: https://www.gregmat.com/ | F23: Paid for the most part.
A24: GRE-003 | B24: =IF(A24="","",IF(COUNTIF(dMAT!A:A,A24)>0,"dMAT",IF(COUNTIF(GRE!A:A,A24)>0,"GRE",IF(COUNTIF(IELTS!A:A,A24)>0,"IELTS",IF(COUNTIF(GMAT!A:A,A24)>0,"GMAT",IF(COUNTIF(German!A:A,A24)>0,"GERMAN","Not Found")))))) -> GRE | C24: {=IF(A24="","",IFNA(_xlfn.XLOOKUP(A24,dMAT!A:A,dMAT!B:F),IFNA(_xlfn.XLOOKUP(A24,GRE!A:A,GRE!B:F),IFNA(_xlfn.XLOOKUP(A24,IELTS!A:A,IELTS!B:F),IFNA(_xlfn.XLOOKUP(A24,GMAT!A:A,GMAT!B:F),IFNA(_xlfn.XLOOKUP(A24,German!A:A,German!B:F),"Not Found"))))))} -> GRE Information Bulletin | D24: Official material | E24: https://drive.google.com/file/d/1y1mNRPF4AaUNgXPSkKpbowYdn1Rd_WX-/view
A25: GRE-004 | B25: =IF(A25="","",IF(COUNTIF(dMAT!A:A,A25)>0,"dMAT",IF(COUNTIF(GRE!A:A,A25)>0,"GRE",IF(COUNTIF(IELTS!A:A,A25)>0,"IELTS",IF(COUNTIF(GMAT!A:A,A25)>0,"GMAT",IF(COUNTIF(German!A:A,A25)>0,"GERMAN","Not Found")))))) -> GRE | C25: {=IF(A25="","",IFNA(_xlfn.XLOOKUP(A25,dMAT!A:A,dMAT!B:F),IFNA(_xlfn.XLOOKUP(A25,GRE!A:A,GRE!B:F),IFNA(_xlfn.XLOOKUP(A25,IELTS!A:A,IELTS!B:F),IFNA(_xlfn.XLOOKUP(A25,GMAT!A:A,GMAT!B:F),IFNA(_xlfn.XLOOKUP(A25,German!A:A,German!B:F),"Not Found"))))))} -> ETS GRE Quantitative Reasoning | D25: Official material | E25: https://drive.google.com/file/d/1KHSUhx2yKvf1g2NVVdNh1VdZ8vv7CtFp/view
A26: GRE-005 | B26: =IF(A26="","",IF(COUNTIF(dMAT!A:A,A26)>0,"dMAT",IF(COUNTIF(GRE!A:A,A26)>0,"GRE",IF(COUNTIF(IELTS!A:A,A26)>0,"IELTS",IF(COUNTIF(GMAT!A:A,A26)>0,"GMAT",IF(COUNTIF(German!A:A,A26)>0,"GERMAN","Not Found")))))) -> GRE | C26: {=IF(A26="","",IFNA(_xlfn.XLOOKUP(A26,dMAT!A:A,dMAT!B:F),IFNA(_xlfn.XLOOKUP(A26,GRE!A:A,GRE!B:F),IFNA(_xlfn.XLOOKUP(A26,IELTS!A:A,IELTS!B:F),IFNA(_xlfn.XLOOKUP(A26,GMAT!A:A,GMAT!B:F),IFNA(_xlfn.XLOOKUP(A26,German!A:A,German!B:F),"Not Found"))))))} -> ETS GRE Verbal Reasoning | D26: Official material | E26: https://drive.google.com/file/d/1h7grvpWMfTzONhH4rC0AO5dckiXV4ThL/view
A27: GRE-006 | B27: =IF(A27="","",IF(COUNTIF(dMAT!A:A,A27)>0,"dMAT",IF(COUNTIF(GRE!A:A,A27)>0,"GRE",IF(COUNTIF(IELTS!A:A,A27)>0,"IELTS",IF(COUNTIF(GMAT!A:A,A27)>0,"GMAT",IF(COUNTIF(German!A:A,A27)>0,"GERMAN","Not Found")))))) -> GRE | C27: {=IF(A27="","",IFNA(_xlfn.XLOOKUP(A27,dMAT!A:A,dMAT!B:F),IFNA(_xlfn.XLOOKUP(A27,GRE!A:A,GRE!B:F),IFNA(_xlfn.XLOOKUP(A27,IELTS!A:A,IELTS!B:F),IFNA(_xlfn.XLOOKUP(A27,GMAT!A:A,GMAT!B:F),IFNA(_xlfn.XLOOKUP(A27,German!A:A,German!B:F),"Not Found"))))))} -> GRE Issue Pool (essay topics) | D27: Official material | E27: https://drive.google.com/file/d/17PKllrsUIDzocx792HmADiGC743A2d5R/view
A28: GRE-007 | B28: =IF(A28="","",IF(COUNTIF(dMAT!A:A,A28)>0,"dMAT",IF(COUNTIF(GRE!A:A,A28)>0,"GRE",IF(COUNTIF(IELTS!A:A,A28)>0,"IELTS",IF(COUNTIF(GMAT!A:A,A28)>0,"GMAT",IF(COUNTIF(German!A:A,A28)>0,"GERMAN","Not Found")))))) -> GRE | C28: {=IF(A28="","",IFNA(_xlfn.XLOOKUP(A28,dMAT!A:A,dMAT!B:F),IFNA(_xlfn.XLOOKUP(A28,GRE!A:A,GRE!B:F),IFNA(_xlfn.XLOOKUP(A28,IELTS!A:A,IELTS!B:F),IFNA(_xlfn.XLOOKUP(A28,GMAT!A:A,GMAT!B:F),IFNA(_xlfn.XLOOKUP(A28,German!A:A,German!B:F),"Not Found"))))))} -> GRE Math Review | D28: Official material | E28: https://drive.google.com/file/d/1Ia7OQJiol8kawU5rZQW14_5tNyW148ea/view
A29: GRE-008 | B29: =IF(A29="","",IF(COUNTIF(dMAT!A:A,A29)>0,"dMAT",IF(COUNTIF(GRE!A:A,A29)>0,"GRE",IF(COUNTIF(IELTS!A:A,A29)>0,"IELTS",IF(COUNTIF(GMAT!A:A,A29)>0,"GMAT",IF(COUNTIF(German!A:A,A29)>0,"GERMAN","Not Found")))))) -> GRE | C29: {=IF(A29="","",IFNA(_xlfn.XLOOKUP(A29,dMAT!A:A,dMAT!B:F),IFNA(_xlfn.XLOOKUP(A29,GRE!A:A,GRE!B:F),IFNA(_xlfn.XLOOKUP(A29,IELTS!A:A,IELTS!B:F),IFNA(_xlfn.XLOOKUP(A29,GMAT!A:A,GMAT!B:F),IFNA(_xlfn.XLOOKUP(A29,German!A:A,German!B:F),"Not Found"))))))} -> The Official Guide to the GRE General Test, 3rd Edition | D29: Official material | E29: https://drive.google.com/file/d/14S641cvc-BBAngjoCSAktl0j2XyMyyrU/view
A30: GRE-009 | B30: =IF(A30="","",IF(COUNTIF(dMAT!A:A,A30)>0,"dMAT",IF(COUNTIF(GRE!A:A,A30)>0,"GRE",IF(COUNTIF(IELTS!A:A,A30)>0,"IELTS",IF(COUNTIF(GMAT!A:A,A30)>0,"GMAT",IF(COUNTIF(German!A:A,A30)>0,"GERMAN","Not Found")))))) -> GRE | C30: {=IF(A30="","",IFNA(_xlfn.XLOOKUP(A30,dMAT!A:A,dMAT!B:F),IFNA(_xlfn.XLOOKUP(A30,GRE!A:A,GRE!B:F),IFNA(_xlfn.XLOOKUP(A30,IELTS!A:A,IELTS!B:F),IFNA(_xlfn.XLOOKUP(A30,GMAT!A:A,GMAT!B:F),IFNA(_xlfn.XLOOKUP(A30,German!A:A,German!B:F),"Not Found"))))))} -> GRE Big Book | D30: PDF / Guide | E30: https://drive.google.com/file/d/1D_w_zzQZjK16NYEA_-A53tLLlOEpKYFW/view
A31: GRE-010 | B31: =IF(A31="","",IF(COUNTIF(dMAT!A:A,A31)>0,"dMAT",IF(COUNTIF(GRE!A:A,A31)>0,"GRE",IF(COUNTIF(IELTS!A:A,A31)>0,"IELTS",IF(COUNTIF(GMAT!A:A,A31)>0,"GMAT",IF(COUNTIF(German!A:A,A31)>0,"GERMAN","Not Found")))))) -> GRE | C31: {=IF(A31="","",IFNA(_xlfn.XLOOKUP(A31,dMAT!A:A,dMAT!B:F),IFNA(_xlfn.XLOOKUP(A31,GRE!A:A,GRE!B:F),IFNA(_xlfn.XLOOKUP(A31,IELTS!A:A,IELTS!B:F),IFNA(_xlfn.XLOOKUP(A31,GMAT!A:A,GMAT!B:F),IFNA(_xlfn.XLOOKUP(A31,German!A:A,German!B:F),"Not Found"))))))} -> Manhattan Prep GRE 5 lb. Book | D31: PDF / Guide | E31: https://drive.google.com/file/d/1o-H4zVpVu_9hoPIqlrl7qFswwSn_nZZH/view
A32: GRE-011 | B32: =IF(A32="","",IF(COUNTIF(dMAT!A:A,A32)>0,"dMAT",IF(COUNTIF(GRE!A:A,A32)>0,"GRE",IF(COUNTIF(IELTS!A:A,A32)>0,"IELTS",IF(COUNTIF(GMAT!A:A,A32)>0,"GMAT",IF(COUNTIF(German!A:A,A32)>0,"GERMAN","Not Found")))))) -> GRE | C32: {=IF(A32="","",IFNA(_xlfn.XLOOKUP(A32,dMAT!A:A,dMAT!B:F),IFNA(_xlfn.XLOOKUP(A32,GRE!A:A,GRE!B:F),IFNA(_xlfn.XLOOKUP(A32,IELTS!A:A,IELTS!B:F),IFNA(_xlfn.XLOOKUP(A32,GMAT!A:A,GMAT!B:F),IFNA(_xlfn.XLOOKUP(A32,German!A:A,German!B:F),"Not Found"))))))} -> 1,014 GRE Practice Questions - Princeton Review (excerpt) | D32: PDF / Guide | E32: https://drive.google.com/file/d/1WnXulhAJWTVc9ioYCqiQmQC2HSVwaD1a/view
A33: GRE-012 | B33: =IF(A33="","",IF(COUNTIF(dMAT!A:A,A33)>0,"dMAT",IF(COUNTIF(GRE!A:A,A33)>0,"GRE",IF(COUNTIF(IELTS!A:A,A33)>0,"IELTS",IF(COUNTIF(GMAT!A:A,A33)>0,"GMAT",IF(COUNTIF(German!A:A,A33)>0,"GERMAN","Not Found")))))) -> GRE | C33: {=IF(A33="","",IFNA(_xlfn.XLOOKUP(A33,dMAT!A:A,dMAT!B:F),IFNA(_xlfn.XLOOKUP(A33,GRE!A:A,GRE!B:F),IFNA(_xlfn.XLOOKUP(A33,IELTS!A:A,IELTS!B:F),IFNA(_xlfn.XLOOKUP(A33,GMAT!A:A,GMAT!B:F),IFNA(_xlfn.XLOOKUP(A33,German!A:A,German!B:F),"Not Found"))))))} -> Conquering GRE Math | D33: PDF / Guide | E33: https://drive.google.com/file/d/1LWbW1h33Hzb9iXlovqpXYpCcdqII8F9J/view
A34: GRE-013 | B34: =IF(A34="","",IF(COUNTIF(dMAT!A:A,A34)>0,"dMAT",IF(COUNTIF(GRE!A:A,A34)>0,"GRE",IF(COUNTIF(IELTS!A:A,A34)>0,"IELTS",IF(COUNTIF(GMAT!A:A,A34)>0,"GMAT",IF(COUNTIF(German!A:A,A34)>0,"GERMAN","Not Found")))))) -> GRE | C34: {=IF(A34="","",IFNA(_xlfn.XLOOKUP(A34,dMAT!A:A,dMAT!B:F),IFNA(_xlfn.XLOOKUP(A34,GRE!A:A,GRE!B:F),IFNA(_xlfn.XLOOKUP(A34,IELTS!A:A,IELTS!B:F),IFNA(_xlfn.XLOOKUP(A34,GMAT!A:A,GMAT!B:F),IFNA(_xlfn.XLOOKUP(A34,German!A:A,German!B:F),"Not Found"))))))} -> GRE Math Strategies - Manhattan Prep 2018 | D34: PDF / Guide | E34: https://drive.google.com/file/d/14M9Jt0ceUaLSMwK2JR8b5ChrKLbvwwFB/view
A35: GRE-014 | B35: =IF(A35="","",IF(COUNTIF(dMAT!A:A,A35)>0,"dMAT",IF(COUNTIF(GRE!A:A,A35)>0,"GRE",IF(COUNTIF(IELTS!A:A,A35)>0,"IELTS",IF(COUNTIF(GMAT!A:A,A35)>0,"GMAT",IF(COUNTIF(German!A:A,A35)>0,"GERMAN","Not Found")))))) -> GRE | C35: {=IF(A35="","",IFNA(_xlfn.XLOOKUP(A35,dMAT!A:A,dMAT!B:F),IFNA(_xlfn.XLOOKUP(A35,GRE!A:A,GRE!B:F),IFNA(_xlfn.XLOOKUP(A35,IELTS!A:A,IELTS!B:F),IFNA(_xlfn.XLOOKUP(A35,GMAT!A:A,GMAT!B:F),IFNA(_xlfn.XLOOKUP(A35,German!A:A,German!B:F),"Not Found"))))))} -> Cracking the GRE Premium 2018 - Princeton Review | D35: PDF / Guide | E35: https://drive.google.com/file/d/1y-LEZXPJ-h3gtwD1emCyAWJ9wjO9Go5_/view
... A43: GRE-022 | B43: =IF(A43="","",IF(COUNTIF(dMAT!A:A,A43)>0,"dMAT",IF(COUNTIF(GRE!A:A,A43)>0,"GRE",IF(COUNTIF(IELTS!A:A,A43)>0,"IELTS",IF(COUNTIF(GMAT!A:A,A43)>0,"GMAT",IF(COUNTIF(German!A:A,A43)>0,"GERMAN","Not Found")))))) -> GRE | C43: {=IF(A43="","",IFNA(_xlfn.XLOOKUP(A43,dMAT!A:A,dMAT!B:F),IFNA(_xlfn.XLOOKUP(A43,GRE!A:A,GRE!B:F),IFNA(_xlfn.XLOOKUP(A43,IELTS!A:A,IELTS!B:F),IFNA(_xlfn.XLOOKUP(A43,GMAT!A:A,GMAT!B:F),IFNA(_xlfn.XLOOKUP(A43,German!A:A,German!B:F),"Not Found"))))))} -> Verbal Workout for the GRE, 6th ed. | D43: PDF / Guide | E43: https://drive.google.com/file/d/1qIgeEJIqPTpyLjhIl3dC4POOz9GbE7sU/view
A44: IELTS-001 | B44: =IF(A44="","",IF(COUNTIF(dMAT!A:A,A44)>0,"dMAT",IF(COUNTIF(GRE!A:A,A44)>0,"GRE",IF(COUNTIF(IELTS!A:A,A44)>0,"IELTS",IF(COUNTIF(GMAT!A:A,A44)>0,"GMAT",IF(COUNTIF(German!A:A,A44)>0,"GERMAN","Not Found")))))) -> IELTS | C44: {=IF(A44="","",IFNA(_xlfn.XLOOKUP(A44,dMAT!A:A,dMAT!B:F),IFNA(_xlfn.XLOOKUP(A44,GRE!A:A,GRE!B:F),IFNA(_xlfn.XLOOKUP(A44,IELTS!A:A,IELTS!B:F),IFNA(_xlfn.XLOOKUP(A44,GMAT!A:A,GMAT!B:F),IFNA(_xlfn.XLOOKUP(A44,German!A:A,German!B:F),"Not Found"))))))} -> IELTS Liz | D44: PDF / Guide | E44: https://ieltsliz.com/ | F44: Overall prep site. BEST | G44: Ruthwik the Great
A45: IELTS-002 | B45: =IF(A45="","",IF(COUNTIF(dMAT!A:A,A45)>0,"dMAT",IF(COUNTIF(GRE!A:A,A45)>0,"GRE",IF(COUNTIF(IELTS!A:A,A45)>0,"IELTS",IF(COUNTIF(GMAT!A:A,A45)>0,"GMAT",IF(COUNTIF(German!A:A,A45)>0,"GERMAN","Not Found")))))) -> IELTS | C45: {=IF(A45="","",IFNA(_xlfn.XLOOKUP(A45,dMAT!A:A,dMAT!B:F),IFNA(_xlfn.XLOOKUP(A45,GRE!A:A,GRE!B:F),IFNA(_xlfn.XLOOKUP(A45,IELTS!A:A,IELTS!B:F),IFNA(_xlfn.XLOOKUP(A45,GMAT!A:A,GMAT!B:F),IFNA(_xlfn.XLOOKUP(A45,German!A:A,German!B:F),"Not Found"))))))} -> IDP IELTS - Listening practice tests | D45: Mock test | E45: https://ieltsidpindia.com/prepare/ielts-listening-test/practice-tests
A46: IELTS-003 | B46: =IF(A46="","",IF(COUNTIF(dMAT!A:A,A46)>0,"dMAT",IF(COUNTIF(GRE!A:A,A46)>0,"GRE",IF(COUNTIF(IELTS!A:A,A46)>0,"IELTS",IF(COUNTIF(GMAT!A:A,A46)>0,"GMAT",IF(COUNTIF(German!A:A,A46)>0,"GERMAN","Not Found")))))) -> IELTS | C46: {=IF(A46="","",IFNA(_xlfn.XLOOKUP(A46,dMAT!A:A,dMAT!B:F),IFNA(_xlfn.XLOOKUP(A46,GRE!A:A,GRE!B:F),IFNA(_xlfn.XLOOKUP(A46,IELTS!A:A,IELTS!B:F),IFNA(_xlfn.XLOOKUP(A46,GMAT!A:A,GMAT!B:F),IFNA(_xlfn.XLOOKUP(A46,German!A:A,German!B:F),"Not Found"))))))} -> IDP IELTS - Reading practice tests | D46: Mock test | E46: https://ieltsidpindia.com/prepare/ielts-reading-test/practice-tests
A47: IELTS-004 | B47: =IF(A47="","",IF(COUNTIF(dMAT!A:A,A47)>0,"dMAT",IF(COUNTIF(GRE!A:A,A47)>0,"GRE",IF(COUNTIF(IELTS!A:A,A47)>0,"IELTS",IF(COUNTIF(GMAT!A:A,A47)>0,"GMAT",IF(COUNTIF(German!A:A,A47)>0,"GERMAN","Not Found")))))) -> IELTS | C47: {=IF(A47="","",IFNA(_xlfn.XLOOKUP(A47,dMAT!A:A,dMAT!B:F),IFNA(_xlfn.XLOOKUP(A47,GRE!A:A,GRE!B:F),IFNA(_xlfn.XLOOKUP(A47,IELTS!A:A,IELTS!B:F),IFNA(_xlfn.XLOOKUP(A47,GMAT!A:A,GMAT!B:F),IFNA(_xlfn.XLOOKUP(A47,German!A:A,German!B:F),"Not Found"))))))} -> IDP IELTS - Writing practice tests | D47: Mock test | E47: https://ieltsidpindia.com/prepare/ielts-writing-test/practice-tests
...

Sheet dMAT
A1: ID | B1: Resource | C1: Type | D1: Link | E1: Notes | F1: Added by
A2: dMAT-001 | B2: dmatprep | C2: Official material | D2: https://drive.google.com/file/d/1ysGWxS0mbBrH8fSVKJ1TkojYYCTuOJxz/view?usp=drive_link | E2: Official main material
A3: dMAT-002 | B3: Vercel App | C3: Mock test | D3: https://dmatprep.vercel.app/
A4: dMAT-003 | B4: dMAT practice (meghchevli) | C4: Practice app | D4: https://dmat.meghchevli.qzz.io/
A5: dMAT-004 | B5: Latin Square practice | C5: Practice app | D5: https://latinsquare.vercel.app/ | E5: no account needed
A6: dMAT-005 | B6: Nbyula dMAT guide | C6: PDF / Guide | D6: https://drive.google.com/file/d/1k816pc1ecIx-UReevHwMbee42DrjhHS-/view?usp=sharing
A7: dMAT-006 | B7: dMAT Grid mock test | C7: Mock test | D7: https://www.dmatgrid.com/mock-test
A8: dMAT-007 | B8: dMat Prep | C8: Mock test | D8: https://dmat-prep.in/ | E8: not a lot of free qs, good for gam
A9: dMAT-008 | B9: dMAT exam structure | C9: PDF / Guide | D9: https://www.d-mat.de/en/
A10: dMAT-009 | B10: Prompt for generating practice questions | C10: Prompt | D10: drive.google.com/file/d/14bkiXQx7qRyhANeGg8nJ0-OHFDwzdAFA/view?usp=drive_link | E10: File access is not given.
A11: dMAT-010 | B11: Career Wise - free dMAT practice app and mock test (APS India) | C11: Mock test | D11: https://www.careerwiseedu.com/dmat-aps-mock-test | E11: Best for full mock test but latin sq are quite easier
A12: dMAT-011 | B12: dMAT Core module Practice | C12: Mock test | D12: https://dmat-website.vercel.app/ | E12: only core module hard questions
A13: dMAT-012 | B13: TestAs Guide for General Academic Module prep | C13: Mock test | D13: https://www.testas.de/fileadmin/bilder/4_pdf-video/1-teilnehmende/230531_digitalertestas_preparatory_materials.pdf
A14: dMAT-013 | B14: Dmat Practice platform | C14: Practice app | D14: http://datasnap.in/
A15: dMAT-014 | B15: Dmat practice and mock test (subject module included - unofficial) | C15: Mock test | D15: https://dmat2026.vercel.app/ | E15: No account and no payment
A16: dMAT-015 | B16: Official Information Guideline for exam | C16: PDF / Guide | D16: https://drive.google.com/file/d/1v1852TLaww_cDXoQRUsDGU_iZYKcpeXU/view?usp=drive_link
A17: dMAT-016 | B17: Latin Square with the timer. | C17: Practice app | D17: https://naikigai.github.io/Dmat-Practice/latin-squares.html
A18: dMAT-017 | B18: General Module Preparation Questions | C18: PDF / Guide | D18: https://drive.google.com/file/d/1gkiuCug_o6I8RxjqFLIAHfRf7a6MvJJJ/view?usp=sharing | E18: great
A19: dMAT-018 | B19: Economics, Social Science, Computational Science Prep | C19: PDF / Guide | D19: https://drive.google.com/file/d/1IqhIaVy6nXQTwI5VTvEkAhM-ExodirxC/view?usp=sharing
A20: dMAT-019 | B20: latin square tips and practice | C20: Practice app | D20: https://latin-squares-tips.vercel.app/
A21: dMAT-020 | B21: Latin Squares Generator TestAS(Recep Dayi) | C21: Practice app | D21: https://recepdayi.com.tr/en/digital-testas-exams-latin-squares/

Sheet GRE
A1: ID | B1: Resource | C1: Type | D1: Link | E1: Notes | F1: Added by
A2: GRE-001 | B2: GRE RESOURCES - shared Drive folder | C2: Other | D2: https://drive.google.com/drive/folders/1yTME8yAtEOoD5JYNelwq5O3FLp-tueJL | E2: Whole folder. Every file inside it is listed individually below.
A3: GRE-002 | B3: Gregmat Website | C3: Website | D3: https://www.gregmat.com/ | E3: Paid for the most part.
A4: GRE-003 | B4: GRE Information Bulletin | C4: Official material | D4: https://drive.google.com/file/d/1y1mNRPF4AaUNgXPSkKpbowYdn1Rd_WX-/view
A5: GRE-004 | B5: ETS GRE Quantitative Reasoning | C5: Official material | D5: https://drive.google.com/file/d/1KHSUhx2yKvf1g2NVVdNh1VdZ8vv7CtFp/view
A6: GRE-005 | B6: ETS GRE Verbal Reasoning | C6: Official material | D6: https://drive.google.com/file/d/1h7grvpWMfTzONhH4rC0AO5dckiXV4ThL/view
A7: GRE-006 | B7: GRE Issue Pool (essay topics) | C7: Official material | D7: https://drive.google.com/file/d/17PKllrsUIDzocx792HmADiGC743A2d5R/view
A8: GRE-007 | B8: GRE Math Review | C8: Official material | D8: https://drive.google.com/file/d/1Ia7OQJiol8kawU5rZQW14_5tNyW148ea/view
A9: GRE-008 | B9: The Official Guide to the GRE General Test, 3rd Edition | C9: Official material | D9: https://drive.google.com/file/d/14S641cvc-BBAngjoCSAktl0j2XyMyyrU/view
A10: GRE-009 | B10: GRE Big Book | C10: PDF / Guide | D10: https://drive.google.com/file/d/1D_w_zzQZjK16NYEA_-A53tLLlOEpKYFW/view
A11: GRE-010 | B11: Manhattan Prep GRE 5 lb. Book | C11: PDF / Guide | D11: https://drive.google.com/file/d/1o-H4zVpVu_9hoPIqlrl7qFswwSn_nZZH/view
A12: GRE-011 | B12: 1,014 GRE Practice Questions - Princeton Review (excerpt) | C12: PDF / Guide | D12: https://drive.google.com/file/d/1WnXulhAJWTVc9ioYCqiQmQC2HSVwaD1a/view
A13: GRE-012 | B13: Conquering GRE Math | C13: PDF / Guide | D13: https://drive.google.com/file/d/1LWbW1h33Hzb9iXlovqpXYpCcdqII8F9J/view
A14: GRE-013 | B14: GRE Math Strategies - Manhattan Prep 2018 | C14: PDF / Guide | D14: https://drive.google.com/file/d/14M9Jt0ceUaLSMwK2JR8b5ChrKLbvwwFB/view
A15: GRE-014 | B15: Cracking the GRE Premium 2018 - Princeton Review | C15: PDF / Guide | D15: https://drive.google.com/file/d/1y-LEZXPJ-h3gtwD1emCyAWJ9wjO9Go5_/view
... A23: GRE-022 | B23: Verbal Workout for the GRE, 6th ed. | C23: PDF / Guide | D23: https://drive.google.com/file/d/1qIgeEJIqPTpyLjhIl3dC4POOz9GbE7sU/view
A24: GRE-023 | B24: Memorizing Vocab APP | C24: Practice app | D24: The Salt Ledger.html | E24: download it and use. it captures atypical words in a story based manner, kindly render this file in a browser. Feel free to edit/review and drop a note if you feel this was useful. | F24: Made by ameya

Sheet IELTS
A1: ID | B1: Resource | C1: Type | D1: Link | E1: Notes | F1: Added by
A2: IELTS-001 | B2: IELTS Liz | C2: PDF / Guide | D2: https://ieltsliz.com/ | E2: Overall prep site. BEST | F2: Ruthwik the Great
A3: IELTS-002 | B3: IDP IELTS - Listening practice tests | C3: Mock test | D3: https://ieltsidpindia.com/prepare/ielts-listening-test/practice-tests
A4: IELTS-003 | B4: IDP IELTS - Reading practice tests | C4: Mock test | D4: https://ieltsidpindia.com/prepare/ielts-reading-test/practice-tests
A5: IELTS-004 | B5: IDP IELTS - Writing practice tests | C5: Mock test | D5: https://ieltsidpindia.com/prepare/ielts-writing-test/practice-tests
A6: IELTS-005 | B6: IELTS Fastrack - Youtube | C6: Video | D6: https://www.youtube.com/@FasTrackIELTS/featured | E6: some people have used this to prepare in just 4 days
A7: IELTS-006 | B7: Cambridge Practise Test Book 1 | C7: Official material | D7: Cambridge Academic 1 (pdf+audios)
A8: IELTS-007 | B8: Cambridge Practise Test Book 2 | C8: Official material | D8: Cambridge Academic 2 (pdf+audios)
A9: IELTS-008 | B9: Cambridge Practise Test Book 3 | C9: Official material | D9: Cambridge Academic 3 (pdf+audios)
A10: IELTS-009 | B10: Cambridge Practise Test Book 4 | C10: Official material | D10: Cambridge Academic 4 (pdf+audios)
A11: IELTS-010 | B11: Cambridge Practise Test Book 5 | C11: Official material | D11: Cambridge Academic 5 (pdf+audios)
A12: IELTS-011 | B12: Cambridge Practise Test Book 6 | C12: Official material | D12: Cambridge Academic 6 (pdf+audios)
A13: IELTS-012 | B13: Cambridge Practise Test Book 7 | C13: Official material | D13: Cambridge Academic 7 (pdf+audios)
A14: IELTS-013 | B14: Cambridge Practise Test Book 8 | C14: Official material | D14: Cambridge Academic 8 (pdf+audios)
A15: IELTS-014 | B15: Cambridge Practise Test Book 9 | C15: Official material | D15: Cambridge Academic 9 (pdf+audios)
A16: IELTS-015 | B16: Cambridge Practise Test Book 10 | C16: Official material | D16: Cambridge Academic 10 (pdf+audios)
A17: IELTS-016 | B17: Cambridge Practise Test Book 11 | C17: Official material | D17: Cambridge Academic 11 (pdf+audios)
A18: IELTS-017 | B18: Cambridge Practise Test Book 12 | C18: Official material | D18: Cambridge Academic 12 (pdf+audios)
... A25: IELTS-024 | B25: Cambridge Practise Test Book 19 | C25: Official material | D25: Cambridge Academic 19 (pdf+audios)
A26: IELTS-025 | B26: Cambridge Practise Test Book 20 | C26: Official material | D26: Cambridge Academic 20(pdf) | E26: cambridge Acacdemic 1-20 listening audios
A27: IELTS-026 | B27: Cambridge Practise Test Book 21 | C27: Official material | D27: Cambridge Academic 21(pdf) | E27: audios available in this yt video link

Sheet GMAT
A1: ID | B1: Resource | C1: Type | D1: Link | E1: Notes | F1: Added by
A2: GMAT-001 | B2: TEST | C2: Mock test | D2: test.com | E2: Please delete after actual resource is added......

Sheet German
A1: ID | B1: Resource | C1: Type | D1: Link | E1: Notes | F1: Added by
A2: GERMAN-001 | B2: A1-C1 German language | C2: Practice app | D2: A1-C1
A3: GERMAN-002 | B3: Basic german | C3: PDF / Guide | D3: Basic german
A4: GERMAN-003 | B4: German grammer A2 cheatsheet | C4: PDF / Guide | D4: cheetsheet
A5: GERMAN-004 | B5: Top 1000 German words | C5: PDF / Guide | D5: top 1000 german words
A6: GERMAN-005 | B6: Collins_German_3000_words_and_phrases | C6: PDF / Guide | D6: Collins_German_3000_words_and_phrases
A7: GERMAN-006 | B7: Learn German Youtube channel | C7: Video | D7: Learn German
A8: GERMAN-007 | B8: A1- B1 German Language | C8: Practice app | D8: A1-B1 | E8: has free and paid plans
A9: GERMAN-008 | B9: Zertifly exam practice app | C9: Practice app | D9: Zertifly | E9: has free and paid plans

Sheet Temp
A1: ID | B1: Resource | C1: Type | D1: Link | E1: Notes | F1: Added by
A2: TEMP-001 | B2: temp | C2: temp | D2: temp.org | E2: temp please ignore | F2: temp
